Workbook

Sheet 0_Parametros
A1: parametro | B1: valor
A2: P | B2: 0.5
A3: Z | B3: 1.96
A4: ME | B4: 0.0392
A5: DEFF | B5: 1.5
A6: Factor | B6: 1.4
A7: Minimo por celda | B7: 10
A8: Fuente poblacion | B8: Matriz departamental anterior, conteos BDUA marzo 2026
A9: Metodo | B9: 10 por celda + reparto proporcional del remanente + resto mayor; empate por orden de fila

Sheet 1_Departamento_n
A1: region | B1: departamento | C1: poblacion | D1: n_mas | E1: n_deff | F1: n_corregido | G1: meta_sin_redondear | H1: meta_final
A2: Bogotá | B2: BOGOTA D.C. | C2: 7780253 | D2: ='0_Parametros'!B3^2*'0_Parametros'!B2*(1-'0_Parametros'!B2)/'0_Parametros'!B4^2 -> 625 | E2: =D2*'0_Parametros'!B5 -> 937.5 | F2: =E2/(1+E2/C2) -> 937.38705 | G2: =F2*'0_Parametros'!B6 -> 1312.3419 | H2: =ROUNDUP(G2,0) -> 1313
A3: Caribe | B3: ATLANTICO | C3: 2806306 | D3: ='0_Parametros'!B3^2*'0_Parametros'!B2*(1-'0_Parametros'!B2)/'0_Parametros'!B4^2 -> 625 | E3: =D3*'0_Parametros'!B5 -> 937.5 | F3: =E3/(1+E3/C3) -> 937.18691 | G3: =F3*'0_Parametros'!B6 -> 1312.0617 | H3: =ROUNDUP(G3,0) -> 1313
A4: Caribe | B4: BOLIVAR | C4: 2345340 | D4: ='0_Parametros'!B3^2*'0_Parametros'!B2*(1-'0_Parametros'!B2)/'0_Parametros'!B4^2 -> 625 | E4: =D4*'0_Parametros'!B5 -> 937.5 | F4: =E4/(1+E4/C4) -> 937.1254 | G4: =F4*'0_Parametros'!B6 -> 1311.9756 | H4: =ROUNDUP(G4,0) -> 1312
A5: Caribe | B5: CESAR | C5: 1284077 | D5: ='0_Parametros'!B3^2*'0_Parametros'!B2*(1-'0_Parametros'!B2)/'0_Parametros'!B4^2 -> 625 | E5: =D5*'0_Parametros'!B5 -> 937.5 | F5: =E5/(1+E5/C5) -> 936.81603 | G5: =F5*'0_Parametros'!B6 -> 1311.5424 | H5: =ROUNDUP(G5,0) -> 1312
A6: Caribe | B6: CORDOBA | C6: 1670770 | D6: ='0_Parametros'!B3^2*'0_Parametros'!B2*(1-'0_Parametros'!B2)/'0_Parametros'!B4^2 -> 625 | E6: =D6*'0_Parametros'!B5 -> 937.5 | F6: =E6/(1+E6/C6) -> 936.97425 | G6: =F6*'0_Parametros'!B6 -> 1311.7639 | H6: =ROUNDUP(G6,0) -> 1312
A7: Caribe | B7: LA GUAJIRA | C7: 1151490 | D7: ='0_Parametros'!B3^2*'0_Parametros'!B2*(1-'0_Parametros'!B2)/'0_Parametros'!B4^2 -> 625 | E7: =D7*'0_Parametros'!B5 -> 937.5 | F7: =E7/(1+E7/C7) -> 936.73734 | G7: =F7*'0_Parametros'!B6 -> 1311.4323 | H7: =ROUNDUP(G7,0) -> 1312
A8: Caribe | B8: MAGDALENA | C8: 1402034 | D8: ='0_Parametros'!B3^2*'0_Parametros'!B2*(1-'0_Parametros'!B2)/'0_Parametros'!B4^2 -> 625 | E8: =D8*'0_Parametros'!B5 -> 937.5 | F8: =E8/(1+E8/C8) -> 936.87354 | G8: =F8*'0_Parametros'!B6 -> 1311.623 | H8: =ROUNDUP(G8,0) -> 1312
A9: Caribe | B9: SAN ANDRES | C9: 61282 | D9: ='0_Parametros'!B3^2*'0_Parametros'!B2*(1-'0_Parametros'!B2)/'0_Parametros'!B4^2 -> 625 | E9: =D9*'0_Parametros'!B5 -> 937.5 | F9: =E9/(1+E9/C9) -> 923.3741 | G9: =F9*'0_Parametros'!B6 -> 1292.7237 | H9: =ROUNDUP(G9,0) -> 1293
A10: Caribe | B10: SUCRE | C10: 944956 | D10: ='0_Parametros'!B3^2*'0_Parametros'!B2*(1-'0_Parametros'!B2)/'0_Parametros'!B4^2 -> 625 | E10: =D10*'0_Parametros'!B5 -> 937.5 | F10: =E10/(1+E10/C10) -> 936.57082 | G10: =F10*'0_Parametros'!B6 -> 1311.1991 | H10: =ROUNDUP(G10,0) -> 1312
A11: Central | B11: ANTIOQUIA | C11: 6959952 | D11: ='0_Parametros'!B3^2*'0_Parametros'!B2*(1-'0_Parametros'!B2)/'0_Parametros'!B4^2 -> 625 | E11: =D11*'0_Parametros'!B5 -> 937.5 | F11: =E11/(1+E11/C11) -> 937.37374 | G11: =F11*'0_Parametros'!B6 -> 1312.3232 | H11: =ROUNDUP(G11,0) -> 1313
A12: Central | B12: CALDAS | C12: 911331 | D12: ='0_Parametros'!B3^2*'0_Parametros'!B2*(1-'0_Parametros'!B2)/'0_Parametros'!B4^2 -> 625 | E12: =D12*'0_Parametros'!B5 -> 937.5 | F12: =E12/(1+E12/C12) -> 936.53657 | G12: =F12*'0_Parametros'!B6 -> 1311.1512 | H12: =ROUNDUP(G12,0) -> 1312
A13: Central | B13: CAQUETA | C13: 411841 | D13: ='0_Parametros'!B3^2*'0_Parametros'!B2*(1-'0_Parametros'!B2)/'0_Parametros'!B4^2 -> 625 | E13: =D13*'0_Parametros'!B5 -> 937.5 | F13: =E13/(1+E13/C13) -> 935.37076 | G13: =F13*'0_Parametros'!B6 -> 1309.5191 | H13: =ROUNDUP(G13,0) -> 1310
A14: Central | B14: HUILA | C14: 1184153 | D14: ='0_Parametros'!B3^2*'0_Parametros'!B2*(1-'0_Parametros'!B2)/'0_Parametros'!B4^2 -> 625 | E14: =D14*'0_Parametros'!B5 -> 937.5 | F14: =E14/(1+E14/C14) -> 936.75836 | G14: =F14*'0_Parametros'!B6 -> 1311.4617 | H14: =ROUNDUP(G14,0) -> 1312
A15: Central | B15: QUINDIO | C15: 569685 | D15: ='0_Parametros'!B3^2*'0_Parametros'!B2*(1-'0_Parametros'!B2)/'0_Parametros'!B4^2 -> 625 | E15: =D15*'0_Parametros'!B5 -> 937.5 | F15: =E15/(1+E15/C15) -> 935.95974 | G15: =F15*'0_Parametros'!B6 -> 1310.3436 | H15: =ROUNDUP(G15,0) -> 1311
A16: Central | B16: RISARALDA | C16: 1076349 | D16: ='0_Parametros'!B3^2*'0_Parametros'!B2*(1-'0_Parametros'!B2)/'0_Parametros'!B4^2 -> 625 | E16: =D16*'0_Parametros'!B5 -> 937.5 | F16: =E16/(1+E16/C16) -> 936.68415 | G16: =F16*'0_Parametros'!B6 -> 1311.3578 | H16: =ROUNDUP(G16,0) -> 1312
A17: Central | B17: TOLIMA | C17: 1300917 | D17: ='0_Parametros'!B3^2*'0_Parametros'!B2*(1-'0_Parametros'!B2)/'0_Parametros'!B4^2 -> 625 | E17: =D17*'0_Parametros'!B5 -> 937.5 | F17: =E17/(1+E17/C17) -> 936.82488 | G17: =F17*'0_Parametros'!B6 -> 1311.5548 | H17: =ROUNDUP(G17,0) -> 1312
A18: Oriental | B18: BOYACA | C18: 1171268 | D18: ='0_Parametros'!B3^2*'0_Parametros'!B2*(1-'0_Parametros'!B2)/'0_Parametros'!B4^2 -> 625 | E18: =D18*'0_Parametros'!B5 -> 937.5 | F18: =E18/(1+E18/C18) -> 936.75021 | G18: =F18*'0_Parametros'!B6 -> 1311.4503 | H18: =ROUNDUP(G18,0) -> 1312
A19: Oriental | B19: CUNDINAMARCA | C19: 2765132 | D19: ='0_Parametros'!B3^2*'0_Parametros'!B2*(1-'0_Parametros'!B2)/'0_Parametros'!B4^2 -> 625 | E19: =D19*'0_Parametros'!B5 -> 937.5 | F19: =E19/(1+E19/C19) -> 937.18225 | G19: =F19*'0_Parametros'!B6 -> 1312.0552 | H19: =ROUNDUP(G19,0) -> 1313
A20: Oriental | B20: META | C20: 1080475 | D20: ='0_Parametros'!B3^2*'0_Parametros'!B2*(1-'0_Parametros'!B2)/'0_Parametros'!B4^2 -> 625 | E20: =D20*'0_Parametros'!B5 -> 937.5 | F20: =E20/(1+E20/C20) -> 936.68726 | G20: =F20*'0_Parametros'!B6 -> 1311.3622 | H20: =ROUNDUP(G20,0) -> 1312
A21: Oriental | B21: NORTE DE SANTANDER | C21: 1746638 | D21: ='0_Parametros'!B3^2*'0_Parametros'!B2*(1-'0_Parametros'!B2)/'0_Parametros'!B4^2 -> 625 | E21: =D21*'0_Parametros'!B5 -> 937.5 | F21: =E21/(1+E21/C21) -> 936.99707 | G21: =F21*'0_Parametros'!B6 -> 1311.7959 | H21: =ROUNDUP(G21,0) -> 1312
A22: Oriental | B22: SANTANDER | C22: 2270133 | D22: ='0_Parametros'!B3^2*'0_Parametros'!B2*(1-'0_Parametros'!B2)/'0_Parametros'!B4^2 -> 625 | E22: =D22*'0_Parametros'!B5 -> 937.5 | F22: =E22/(1+E22/C22) -> 937.113 | G22: =F22*'0_Parametros'!B6 -> 1311.9582 | H22: =ROUNDUP(G22,0) -> 1312
A23: Orinoquía-Amazonía | B23: AMAZONAS | C23: 76629 | D23: ='0_Parametros'!B3^2*'0_Parametros'!B2*(1-'0_Parametros'!B2)/'0_Parametros'!B4^2 -> 625 | E23: =D23*'0_Parametros'!B5 -> 937.5 | F23: =E23/(1+E23/C23) -> 926.169 | G23: =F23*'0_Parametros'!B6 -> 1296.6366 | H23: =ROUNDUP(G23,0) -> 1297
A24: Orinoquía-Amazonía | B24: ARAUCA | C24: 319492 | D24: ='0_Parametros'!B3^2*'0_Parametros'!B2*(1-'0_Parametros'!B2)/'0_Parametros'!B4^2 -> 625 | E24: =D24*'0_Parametros'!B5 -> 937.5 | F24: =E24/(1+E24/C24) -> 934.7571 | G24: =F24*'0_Parametros'!B6 -> 1308.6599 | H24: =ROUNDUP(G24,0) -> 1309
A25: Orinoquía-Amazonía | B25: CASANARE | C25: 434332 | D25: ='0_Parametros'!B3^2*'0_Parametros'!B2*(1-'0_Parametros'!B2)/'0_Parametros'!B4^2 -> 625 | E25: =D25*'0_Parametros'!B5 -> 937.5 | F25: =E25/(1+E25/C25) -> 935.48078 | G25: =F25*'0_Parametros'!B6 -> 1309.6731 | H25: =ROUNDUP(G25,0) -> 1310
A26: Orinoquía-Amazonía | B26: GUAINIA | C26: 54596 | D26: ='0_Parametros'!B3^2*'0_Parametros'!B2*(1-'0_Parametros'!B2)/'0_Parametros'!B4^2 -> 625 | E26: =D26*'0_Parametros'!B5 -> 937.5 | F26: =E26/(1+E26/C26) -> 921.6734 | G26: =F26*'0_Parametros'!B6 -> 1290.3428 | H26: =ROUNDUP(G26,0) -> 1291
A27: Orinoquía-Amazonía | B27: GUAVIARE | C27: 85937 | D27: ='0_Parametros'!B3^2*'0_Parametros'!B2*(1-'0_Parametros'!B2)/'0_Parametros'!B4^2 -> 625 | E27: =D27*'0_Parametros'!B5 -> 937.5 | F27: =E27/(1+E27/C27) -> 927.38304 | G27: =F27*'0_Parametros'!B6 -> 1298.3362 | H27: =ROUNDUP(G27,0) -> 1299
A28: Orinoquía-Amazonía | B28: PUTUMAYO | C28: 332640 | D28: ='0_Parametros'!B3^2*'0_Parametros'!B2*(1-'0_Parametros'!B2)/'0_Parametros'!B4^2 -> 625 | E28: =D28*'0_Parametros'!B5 -> 937.5 | F28: =E28/(1+E28/C28) -> 934.86521 | G28: =F28*'0_Parametros'!B6 -> 1308.8113 | H28: =ROUNDUP(G28,0) -> 1309
A29: Orinoquía-Amazonía | B29: VAUPES | C29: 34307 | D29: ='0_Parametros'!B3^2*'0_Parametros'!B2*(1-'0_Parametros'!B2)/'0_Parametros'!B4^2 -> 625 | E29: =D29*'0_Parametros'!B5 -> 937.5 | F29: =E29/(1+E29/C29) -> 912.5626 | G29: =F29*'0_Parametros'!B6 -> 1277.5876 | H29: =ROUNDUP(G29,0) -> 1278
A30: Orinoquía-Amazonía | B30: VICHADA | C30: 90089 | D30: ='0_Parametros'!B3^2*'0_Parametros'!B2*(1-'0_Parametros'!B2)/'0_Parametros'!B4^2 -> 625 | E30: =D30*'0_Parametros'!B5 -> 937.5 | F30: =E30/(1+E30/C30) -> 927.8445 | G30: =F30*'0_Parametros'!B6 -> 1298.9823 | H30: =ROUNDUP(G30,0) -> 1299
A31: Pacífica | B31: CAUCA | C31: 1329172 | D31: ='0_Parametros'!B3^2*'0_Parametros'!B2*(1-'0_Parametros'!B2)/'0_Parametros'!B4^2 -> 625 | E31: =D31*'0_Parametros'!B5 -> 937.5 | F31: =E31/(1+E31/C31) -> 936.83922 | G31: =F31*'0_Parametros'!B6 -> 1311.5749 | H31: =ROUNDUP(G31,0) -> 1312
A32: Pacífica | B32: CHOCO | C32: 441422 | D32: ='0_Parametros'!B3^2*'0_Parametros'!B2*(1-'0_Parametros'!B2)/'0_Parametros'!B4^2 -> 625 | E32: =D32*'0_Parametros'!B5 -> 937.5 | F32: =E32/(1+E32/C32) -> 935.51314 | G32: =F32*'0_Parametros'!B6 -> 1309.7184 | H32: =ROUNDUP(G32,0) -> 1310
A33: Pacífica | B33: NARINO | C33: 1447016 | D33: ='0_Parametros'!B3^2*'0_Parametros'!B2*(1-'0_Parametros'!B2)/'0_Parametros'!B4^2 -> 625 | E33: =D33*'0_Parametros'!B5 -> 937.5 | F33: =E33/(1+E33/C33) -> 936.893 | G33: =F33*'0_Parametros'!B6 -> 1311.6502 | H33: =ROUNDUP(G33,0) -> 1312
A34: Pacífica | B34: VALLE | C34: 4628732 | D34: ='0_Parametros'!B3^2*'0_Parametros'!B2*(1-'0_Parametros'!B2)/'0_Parametros'!B4^2 -> 625 | E34: =D34*'0_Parametros'!B5 -> 937.5 | F34: =E34/(1+E34/C34) -> 937.31016 | G34: =F34*'0_Parametros'!B6 -> 1312.2342 | H34: =ROUNDUP(G34,0) -> 1313

Sheet 2_Asignacion_Celda
A1: region | B1: departamento | C1: regimen | D1: sexo | E1: edad | F1: zona | G1: poblacion_celda | H1: poblacion_depto | I1: meta_depto | J1: minimo | K1: remanente_proporcional | L1: entero | M1: fraccion | N1: orden_resto | O1: meta_celda
A2: Bogotá | B2: BOGOTA D.C. | C2: CONTRIBUTIVO | D2: FEMENINO | E2: 00-09 | F2: URBANO | G2: 229519 | H2: ='1_Departamento_n'!C2 -> 7780253 | I2: ='1_Departamento_n'!H2 -> 1313 | J2: ='0_Parametros'!B7 -> 10 | K2: =(I2-SUM($J$2:$J$57))*G2/H2 -> 22.213649 | L2: =INT(K2) -> 22 | M2: =K2-L2 -> 0.21364871 | N2: =COUNTIF($M$2:$M$57,">"&M2)+COUNTIF($M$2:M2,M2) -> 50 | O2: =J2+L2+IF(N2<=I2-SUM($J$2:$J$57)-SUM($L$2:$L$57),1,0) -> 32
A3: Bogotá | B3: BOGOTA D.C. | C3: CONTRIBUTIVO | D3: FEMENINO | E3: 00-09 | F3: RURAL | G3: 4241 | H3: ='1_Departamento_n'!C2 -> 7780253 | I3: ='1_Departamento_n'!H2 -> 1313 | J3: ='0_Parametros'!B7 -> 10 | K3: =(I3-SUM($J$2:$J$57))*G3/H3 -> 0.41045876 | L3: =INT(K3) -> 0 | M3: =K3-L3 -> 0.41045876 | N3: =COUNTIF($M$2:$M$57,">"&M3)+COUNTIF($M$2:M3,M3) -> 28 | O3: =J3+L3+IF(N3<=I3-SUM($J$2:$J$57)-SUM($L$2:$L$57),1,0) -> 10
A4: Bogotá | B4: BOGOTA D.C. | C4: CONTRIBUTIVO | D4: FEMENINO | E4: 10-19 | F4: URBANO | G4: 354667 | H4: ='1_Departamento_n'!C2 -> 7780253 | I4: ='1_Departamento_n'!H2 -> 1313 | J4: ='0_Parametros'!B7 -> 10 | K4: =(I4-SUM($J$2:$J$57))*G4/H4 -> 34.325908 | L4: =INT(K4) -> 34 | M4: =K4-L4 -> 0.3259083 | N4: =COUNTIF($M$2:$M$57,">"&M4)+COUNTIF($M$2:M4,M4) -> 39 | O4: =J4+L4+IF(N4<=I4-SUM($J$2:$J$57)-SUM($L$2:$L$57),1,0) -> 44
A5: Bogotá | B5: BOGOTA D.C. | C5: CONTRIBUTIVO | D5: FEMENINO | E5: 10-19 | F5: RURAL | G5: 3820 | H5: ='1_Departamento_n'!C2 -> 7780253 | I5: ='1_Departamento_n'!H2 -> 1313 | J5: ='0_Parametros'!B7 -> 10 | K5: =(I5-SUM($J$2:$J$57))*G5/H5 -> 0.36971291 | L5: =INT(K5) -> 0 | M5: =K5-L5 -> 0.36971291 | N5: =COUNTIF($M$2:$M$57,">"&M5)+COUNTIF($M$2:M5,M5) -> 31 | O5: =J5+L5+IF(N5<=I5-SUM($J$2:$J$57)-SUM($L$2:$L$57),1,0) -> 10
A6: Bogotá | B6: BOGOTA D.C. | C6: CONTRIBUTIVO | D6: FEMENINO | E6: 20-29 | F6: URBANO | G6: 477032 | H6: ='1_Departamento_n'!C2 -> 7780253 | I6: ='1_Departamento_n'!H2 -> 1313 | J6: ='0_Parametros'!B7 -> 10 | K6: =(I6-SUM($J$2:$J$57))*G6/H6 -> 46.168819 | L6: =INT(K6) -> 46 | M6: =K6-L6 -> 0.16881945 | N6: =COUNTIF($M$2:$M$57,">"&M6)+COUNTIF($M$2:M6,M6) -> 52 | O6: =J6+L6+IF(N6<=I6-SUM($J$2:$J$57)-SUM($L$2:$L$57),1,0) -> 56
A7: Bogotá | B7: BOGOTA D.C. | C7: CONTRIBUTIVO | D7: FEMENINO | E7: 20-29 | F7: RURAL | G7: 9514 | H7: ='1_Departamento_n'!C2 -> 7780253 | I7: ='1_Departamento_n'!H2 -> 1313 | J7: ='0_Parametros'!B7 -> 10 | K7: =(I7-SUM($J$2:$J$57))*G7/H7 -> 0.92079808 | L7: =INT(K7) -> 0 | M7: =K7-L7 -> 0.92079808 | N7: =COUNTIF($M$2:$M$57,">"&M7)+COUNTIF($M$2:M7,M7) -> 4 | O7: =J7+L7+IF(N7<=I7-SUM($J$2:$J$57)-SUM($L$2:$L$57),1,0) -> 11
A8: Bogotá | B8: BOGOTA D.C. | C8: CONTRIBUTIVO | D8: FEMENINO | E8: 30-39 | F8: URBANO | G8: 545362 | H8: ='1_Departamento_n'!C2 -> 7780253 | I8: ='1_Departamento_n'!H2 -> 1313 | J8: ='0_Parametros'!B7 -> 10 | K8: =(I8-SUM($J$2:$J$57))*G8/H8 -> 52.782035 | L8: =INT(K8) -> 52 | M8: =K8-L8 -> 0.78203498 | N8: =COUNTIF($M$2:$M$57,">"&M8)+COUNTIF($M$2:M8,M8) -> 10 | O8: =J8+L8+IF(N8<=I8-SUM($J$2:$J$57)-SUM($L$2:$L$57),1,0) -> 63
A9: Bogotá | B9: BOGOTA D.C. | C9: CONTRIBUTIVO | D9: FEMENINO | E9: 30-39 | F9: RURAL | G9: 6293 | H9: ='1_Departamento_n'!C2 -> 7780253 | I9: ='1_Departamento_n'!H2 -> 1313 | J9: ='0_Parametros'!B7 -> 10 | K9: =(I9-SUM($J$2:$J$57))*G9/H9 -> 0.60905847 | L9: =INT(K9) -> 0 | M9: =K9-L9 -> 0.60905847 | N9: =COUNTIF($M$2:$M$57,">"&M9)+COUNTIF($M$2:M9,M9) -> 15 | O9: =J9+L9+IF(N9<=I9-SUM($J$2:$J$57)-SUM($L$2:$L$57),1,0) -> 11
A10: Bogotá | B10: BOGOTA D.C. | C10: CONTRIBUTIVO | D10: FEMENINO | E10: 40-49 | F10: URBANO | G10: 467347 | H10: ='1_Departamento_n'!C2 -> 7780253 | I10: ='1_Departamento_n'!H2 -> 1313 | J10: ='0_Parametros'!B7 -> 10 | K10: =(I10-SUM($J$2:$J$57))*G10/H10 -> 45.231471 | L10: =INT(K10) -> 45 | M10: =K10-L10 -> 0.23147139 | N10: =COUNTIF($M$2:$M$57,">"&M10)+COUNTIF($M$2:M10,M10) -> 49 | O10: =J10+L10+IF(N10<=I10-SUM($J$2:$J$57)-SUM($L$2:$L$57),1,0) -> 55
A11: Bogotá | B11: BOGOTA D.C. | C11: CONTRIBUTIVO | D11: FEMENINO | E11: 40-49 | F11: RURAL | G11: 3806 | H11: ='1_Departamento_n'!C2 -> 7780253 | I11: ='1_Departamento_n'!H2 -> 1313 | J11: ='0_Parametros'!B7 -> 10 | K11: =(I11-SUM($J$2:$J$57))*G11/H11 -> 0.36835794 | L11: =INT(K11) -> 0 | M11: =K11-L11 -> 0.36835794 | N11: =COUNTIF($M$2:$M$57,">"&M11)+COUNTIF($M$2:M11,M11) -> 32 | O11: =J11+L11+IF(N11<=I11-SUM($J$2:$J$57)-SUM($L$2:$L$57),1,0) -> 10
A12: Bogotá | B12: BOGOTA D.C. | C12: CONTRIBUTIVO | D12: FEMENINO | E12: 50-59 | F12: URBANO | G12: 383142 | H12: ='1_Departamento_n'!C2 -> 7780253 | I12: ='1_Departamento_n'!H2 -> 1313 | J12: ='0_Parametros'!B7 -> 10 | K12: =(I12-SUM($J$2:$J$57))*G12/H12 -> 37.081818 | L12: =INT(K12) -> 37 | M12: =K12-L12 -> 0.081818033 | N12: =COUNTIF($M$2:$M$57,">"&M12)+COUNTIF($M$2:M12,M12) -> 55 | O12: =J12+L12+IF(N12<=I12-SUM($J$2:$J$57)-SUM($L$2:$L$57),1,0) -> 47
A13: Bogotá | B13: BOGOTA D.C. | C13: CONTRIBUTIVO | D13: FEMENINO | E13: 50-59 | F13: RURAL | G13: 2579 | H13: ='1_Departamento_n'!C2 -> 7780253 | I13: ='1_Departamento_n'!H2 -> 1313 | J13: ='0_Parametros'!B7 -> 10 | K13: =(I13-SUM($J$2:$J$57))*G13/H13 -> 0.24960461 | L13: =INT(K13) -> 0 | M13: =K13-L13 -> 0.24960461 | N13: =COUNTIF($M$2:$M$57,">"&M13)+COUNTIF($M$2:M13,M13) -> 46 | O13: =J13+L13+IF(N13<=I13-SUM($J$2:$J$57)-SUM($L$2:$L$57),1,0) -> 10
A14: Bogotá | B14: BOGOTA D.C. | C14: CONTRIBUTIVO | D14: FEMENINO | E14: 60 o más | F14: URBANO | G14: 638441 | H14: ='1_Departamento_n'!C2 -> 7780253 | I14: ='1_Departamento_n'!H2 -> 1313 | J14: ='0_Parametros'!B7 -> 10 | K14: =(I14-SUM($J$2:$J$57))*G14/H14 -> 61.790545 | L14: =INT(K14) -> 61 | M14: =K14-L14 -> 0.79054499 | N14: =COUNTIF($M$2:$M$57,">"&M14)+COUNTIF($M$2:M14,M14) -> 9 | O14: =J14+L14+IF(N14<=I14-SUM($J$2:$J$57)-SUM($L$2:$L$57),1,0) -> 72
A15: Bogotá | B15: BOGOTA D.C. | C15: CONTRIBUTIVO | D15: FEMENINO | E15: 60 o más | F15: RURAL | G15: 3360 | H15: ='1_Departamento_n'!C2 -> 7780253 | I15: ='1_Departamento_n'!H2 -> 1313 | J15: ='0_Parametros'!B7 -> 10 | K15: =(I15-SUM($J$2:$J$57))*G15/H15 -> 0.32519251 | L15: =INT(K15) -> 0 | M15: =K15-L15 -> 0.32519251 | N15: =COUNTIF($M$2:$M$57,">"&M15)+COUNTIF($M$2:M15,M15) -> 40 | O15: =J15+L15+IF(N15<=I15-SUM($J$2:$J$57)-SUM($L$2:$L$57),1,0) -> 10
A16: Bogotá | B16: BOGOTA D.C. | C16: CONTRIBUTIVO | D16: MASCULINO | E16: 00-09 | F16: URBANO | G16: 239827 | H16: ='1_Departamento_n'!C2 -> 7780253 | I16: ='1_Departamento_n'!H2 -> 1313 | J16: ='0_Parametros'!B7 -> 10 | K16: =(I16-SUM($J$2:$J$57))*G16/H16 -> 23.211293 | L16: =INT(K16) -> 23 | M16: =K16-L16 -> 0.21129287 | N16: =COUNTIF($M$2:$M$57,">"&M16)+COUNTIF($M$2:M16,M16) -> 51 | O16: =J16+L16+IF(N16<=I16-SUM($J$2:$J$57)-SUM($L$2:$L$57),1,0) -> 33
A17: Bogotá | B17: BOGOTA D.C. | C17: CONTRIBUTIVO | D17: MASCULINO | E17: 00-09 | F17: RURAL | G17: 4438 | H17: ='1_Departamento_n'!C2 -> 7780253 | I17: ='1_Departamento_n'!H2 -> 1313 | J17: ='0_Parametros'!B7 -> 10 | K17: =(I17-SUM($J$2:$J$57))*G17/H17 -> 0.42952511 | L17: =INT(K17) -> 0 | M17: =K17-L17 -> 0.42952511 | N17: =COUNTIF($M$2:$M$57,">"&M17)+COUNTIF($M$2:M17,M17) -> 26 | O17: =J17+L17+IF(N17<=I17-SUM($J$2:$J$57)-SUM($L$2:$L$57),1,0) -> 11
A18: Bogotá | B18: BOGOTA D.C. | C18: CONTRIBUTIVO | D18: MASCULINO | E18: 10-19 | F18: URBANO | G18: 365883 | H18: ='1_Departamento_n'!C2 -> 7780253 | I18: ='1_Departamento_n'!H2 -> 1313 | J18: ='0_Parametros'!B7 -> 10 | K18: =(I18-SUM($J$2:$J$57))*G18/H18 -> 35.411432 | L18: =INT(K18) -> 35 | M18: =K18-L18 -> 0.41143186 | N18: =COUNTIF($M$2:$M$57,">"&M18)+COUNTIF($M$2:M18,M18) -> 27 | O18: =J18+L18+IF(N18<=I18-SUM($J$2:$J$57)-SUM($L$2:$L$57),1,0) -> 45
A19: Bogotá | B19: BOGOTA D.C. | C19: CONTRIBUTIVO | D19: MASCULINO | E19: 10-19 | F19: RURAL | G19: 3793 | H19: ='1_Departamento_n'!C2 -> 7780253 | I19: ='1_Departamento_n'!H2 -> 1313 | J19: ='0_Parametros'!B7 -> 10 | K19: =(I19-SUM($J$2:$J$57))*G19/H19 -> 0.36709976 | L19: =INT(K19) -> 0 | M19: =K19-L19 -> 0.36709976 | N19: =COUNTIF($M$2:$M$57,">"&M19)+COUNTIF($M$2:M19,M19) -> 33 | O19: =J19+L19+IF(N19<=I19-SUM($J$2:$J$57)-SUM($L$2:$L$57),1,0) -> 10
A20: Bogotá | B20: BOGOTA D.C. | C20: CONTRIBUTIVO | D20: MASCULINO | E20: 20-29 | F20: URBANO | G20: 469397 | H20: ='1_Departamento_n'!C2 -> 7780253 | I20: ='1_Departamento_n'!H2 -> 1313 | J20: ='0_Parametros'!B7 -> 10 | K20: =(I20-SUM($J$2:$J$57))*G20/H20 -> 45.429878 | L20: =INT(K20) -> 45 | M20: =K20-L20 -> 0.42987754 | N20: =COUNTIF($M$2:$M$57,">"&M20)+COUNTIF($M$2:M20,M20) -> 25 | O20: =J20+L20+IF(N20<=I20-SUM($J$2:$J$57)-SUM($L$2:$L$57),1,0) -> 56
A21: Bogotá | B21: BOGOTA D.C. | C21: CONTRIBUTIVO | D21: MASCULINO | E21: 20-29 | F21: RURAL | G21: 11469 | H21: ='1_Departamento_n'!C2 -> 7780253 | I21: ='1_Departamento_n'!H2 -> 1313 | J21: ='0_Parametros'!B7 -> 10 | K21: =(I21-SUM($J$2:$J$57))*G21/H21 -> 1.1100098 | L21: =INT(K21) -> 1 | M21: =K21-L21 -> 0.11000979 | N21: =COUNTIF($M$2:$M$57,">"&M21)+COUNTIF($M$2:M21,M21) -> 54 | O21: =J21+L21+IF(N21<=I21-SUM($J$2:$J$57)-SUM($L$2:$L$57),1,0) -> 11
A22: Bogotá | B22: BOGOTA D.C. | C22: CONTRIBUTIVO | D22: MASCULINO | E22: 30-39 | F22: URBANO | G22: 516934 | H22: ='1_Departamento_n'!C2 -> 7780253 | I22: ='1_Departamento_n'!H2 -> 1313 | J22: ='0_Parametros'!B7 -> 10 | K22: =(I22-SUM($J$2:$J$57))*G22/H22 -> 50.030674 | L22: =INT(K22) -> 50 | M22: =K22-L22 -> 0.030674067 | N22: =COUNTIF($M$2:$M$57,">"&M22)+COUNTIF($M$2:M22,M22) -> 56 | O22: =J22+L22+IF(N22<=I22-SUM($J$2:$J$57)-SUM($L$2:$L$57),1,0) -> 60
A23: Bogotá | B23: BOGOTA D.C. | C23: CONTRIBUTIVO | D23: MASCULINO | E23: 30-39 | F23: RURAL | G23: 7545 | H23: ='1_Departamento_n'!C2 -> 7780253 | I23: ='1_Departamento_n'!H2 -> 1313 | J23: ='0_Parametros'!B7 -> 10 | K23: =(I23-SUM($J$2:$J$57))*G23/H23 -> 0.73023139 | L23: =INT(K23) -> 0 | M23: =K23-L23 -> 0.73023139 | N23: =COUNTIF($M$2:$M$57,">"&M23)+COUNTIF($M$2:M23,M23) -> 11 | O23: =J23+L23+IF(N23<=I23-SUM($J$2:$J$57)-SUM($L$2:$L$57),1,0) -> 11
A24: Bogotá | B24: BOGOTA D.C. | C24: CONTRIBUTIVO | D24: MASCULINO | E24: 40-49 | F24: URBANO | G24: 419345 | H24: ='1_Departamento_n'!C2 -> 7780253 | I24: ='1_Departamento_n'!H2 -> 1313 | J24: ='0_Parametros'!B7 -> 10 | K24: =(I24-SUM($J$2:$J$57))*G24/H24 -> 40.585671 | L24: =INT(K24) -> 40 | M24: =K24-L24 -> 0.58567054 | N24: =COUNTIF($M$2:$M$57,">"&M24)+COUNTIF($M$2:M24,M24) -> 16 | O24: =J24+L24+IF(N24<=I24-SUM($J$2:$J$57)-SUM($L$2:$L$57),1,0) -> 51
A25: Bogotá | B25: BOGOTA D.C. | C25: CONTRIBUTIVO | D25: MASCULINO | E25: 40-49 | F25: RURAL | G25: 4195 | H25: ='1_Departamento_n'!C2 -> 7780253 | I25: ='1_Departamento_n'!H2 -> 1313 | J25: ='0_Parametros'!B7 -> 10 | K25: =(I25-SUM($J$2:$J$57))*G25/H25 -> 0.40600672 | L25: =INT(K25) -> 0 | M25: =K25-L25 -> 0.40600672 | N25: =COUNTIF($M$2:$M$57,">"&M25)+COUNTIF($M$2:M25,M25) -> 29 | O25: =J25+L25+IF(N25<=I25-SUM($J$2:$J$57)-SUM($L$2:$L$57),1,0) -> 10
A26: Bogotá | B26: BOGOTA D.C. | C26: CONTRIBUTIVO | D26: MASCULINO | E26: 50-59 | F26: URBANO | G26: 323716 | H26: ='1_Departamento_n'!C2 -> 7780253 | I26: ='1_Departamento_n'!H2 -> 1313 | J26: ='0_Parametros'!B7 -> 10 | K26: =(I26-SUM($J$2:$J$57))*G26/H26 -> 31.330363 | L26: =INT(K26) -> 31 | M26: =K26-L26 -> 0.33036265 | N26: =COUNTIF($M$2:$M$57,">"&M26)+COUNTIF($M$2:M26,M26) -> 38 | O26: =J26+L26+IF(N26<=I26-SUM($J$2:$J$57)-SUM($L$2:$L$57),1,0) -> 41
A27: Bogotá | B27: BOGOTA D.C. | C27: CONTRIBUTIVO | D27: MASCULINO | E27: 50-59 | F27: RURAL | G27: 2623 | H27: ='1_Departamento_n'!C2 -> 7780253 | I27: ='1_Departamento_n'!H2 -> 1313 | J27: ='0_Parametros'!B7 -> 10 | K27: =(I27-SUM($J$2:$J$57))*G27/H27 -> 0.25386308 | L27: =INT(K27) -> 0 | M27: =K27-L27 -> 0.25386308 | N27: =COUNTIF($M$2:$M$57,">"&M27)+COUNTIF($M$2:M27,M27) -> 45 | O27: =J27+L27+IF(N27<=I27-SUM($J$2:$J$57)-SUM($L$2:$L$57),1,0) -> 10
A28: Bogotá | B28: BOGOTA D.C. | C28: CONTRIBUTIVO | D28: MASCULINO | E28: 60 o más | F28: URBANO | G28: 468713 | H28: ='1_Departamento_n'!C2 -> 7780253 | I28: ='1_Departamento_n'!H2 -> 1313 | J28: ='0_Parametros'!B7 -> 10 | K28: =(I28-SUM($J$2:$J$57))*G28/H28 -> 45.363678 | L28: =INT(K28) -> 45 | M28: =K28-L28 -> 0.36367763 | N28: =COUNTIF($M$2:$M$57,">"&M28)+COUNTIF($M$2:M28,M28) -> 34 | O28: =J28+L28+IF(N28<=I28-SUM($J$2:$J$57)-SUM($L$2:$L$57),1,0) -> 55
A29: Bogotá | B29: BOGOTA D.C. | C29: CONTRIBUTIVO | D29: MASCULINO | E29: 60 o más | F29: RURAL | G29: 2974 | H29: ='1_Departamento_n'!C2 -> 7780253 | I29: ='1_Departamento_n'!H2 -> 1313 | J29: ='0_Parametros'!B7 -> 10 | K29: =(I29-SUM($J$2:$J$57))*G29/H29 -> 0.28783408 | L29: =INT(K29) -> 0 | M29: =K29-L29 -> 0.28783408 | N29: =COUNTIF($M$2:$M$57,">"&M29)+COUNTIF($M$2:M29,M29) -> 42 | O29: =J29+L29+IF(N29<=I29-SUM($J$2:$J$57)-SUM($L$2:$L$57),1,0) -> 10
A30: Bogotá | B30: BOGOTA D.C. | C30: SUBSIDIADO | D30: FEMENINO | E30: 00-09 | F30: URBANO | G30: 101851 | H30: ='1_Departamento_n'!C2 -> 7780253 | I30: ='1_Departamento_n'!H2 -> 1313 | J30: ='0_Parametros'!B7 -> 10 | K30: =(I30-SUM($J$2:$J$57))*G30/H30 -> 9.8574947 | L30: =INT(K30) -> 9 | M30: =K30-L30 -> 0.85749474 | N30: =COUNTIF($M$2:$M$57,">"&M30)+COUNTIF($M$2:M30,M30) -> 6 | O30: =J30+L30+IF(N30<=I30-SUM($J$2:$J$57)-SUM($L$2:$L$57),1,0) -> 20
A31: Bogotá | B31: BOGOTA D.C. | C31: SUBSIDIADO | D31: FEMENINO | E31: 00-09 | F31: RURAL | G31: 4862 | H31: ='1_Departamento_n'!C2 -> 7780253 | I31: ='1_Departamento_n'!H2 -> 1313 | J31: ='0_Parametros'!B7 -> 10 | K31: =(I31-SUM($J$2:$J$57))*G31/H31 -> 0.4705613 | L31: =INT(K31) -> 0 | M31: =K31-L31 -> 0.4705613 | N31: =COUNTIF($M$2:$M$57,">"&M31)+COUNTIF($M$2:M31,M31) -> 22 | O31: =J31+L31+IF(N31<=I31-SUM($J$2:$J$57)-SUM($L$2:$L$57),1,0) -> 11
A32: Bogotá | B32: BOGOTA D.C. | C32: SUBSIDIADO | D32: FEMENINO | E32: 10-19 | F32: URBANO | G32: 129928 | H32: ='1_Departamento_n'!C2 -> 7780253 | I32: ='1_Departamento_n'!H2 -> 1313 | J32: ='0_Parametros'!B7 -> 10 | K32: =(I32-SUM($J$2:$J$57))*G32/H32 -> 12.574885 | L32: =INT(K32) -> 12 | M32: =K32-L32 -> 0.57488465 | N32: =COUNTIF($M$2:$M$57,">"&M32)+COUNTIF($M$2:M32,M32) -> 17 | O32: =J32+L32+IF(N32<=I32-SUM($J$2:$J$57)-SUM($L$2:$L$57),1,0) -> 23
A33: Bogotá | B33: BOGOTA D.C. | C33: SUBSIDIADO | D33: FEMENINO | E33: 10-19 | F33: RURAL | G33: 5045 | H33: ='1_Departamento_n'!C2 -> 7780253 | I33: ='1_Departamento_n'!H2 -> 1313 | J33: ='0_Parametros'!B7 -> 10 | K33: =(I33-SUM($J$2:$J$57))*G33/H33 -> 0.48827268 | L33: =INT(K33) -> 0 | M33: =K33-L33 -> 0.48827268 | N33: =COUNTIF($M$2:$M$57,">"&M33)+COUNTIF($M$2:M33,M33) -> 21 | O33: =J33+L33+IF(N33<=I33-SUM($J$2:$J$57)-SUM($L$2:$L$57),1,0) -> 11
A34: Bogotá | B34: BOGOTA D.C. | C34: SUBSIDIADO | D34: FEMENINO | E34: 20-29 | F34: URBANO | G34: 147558 | H34: ='1_Departamento_n'!C2 -> 7780253 | I34: ='1_Departamento_n'!H2 -> 1313 | J34: ='0_Parametros'!B7 -> 10 | K34: =(I34-SUM($J$2:$J$57))*G34/H34 -> 14.281177 | L34: =INT(K34) -> 14 | M34: =K34-L34 -> 0.28117749 | N34: =COUNTIF($M$2:$M$57,">"&M34)+COUNTIF($M$2:M34,M34) -> 43 | O34: =J34+L34+IF(N34<=I34-SUM($J$2:$J$57)-SUM($L$2:$L$57),1,0) -> 24
A35: Bogotá | B35: BOGOTA D.C. | C35: SUBSIDIADO | D35: FEMENINO | E35: 20-29 | F35: RURAL | G35: 8419 | H35: ='1_Departamento_n'!C2 -> 7780253 | I35: ='1_Departamento_n'!H2 -> 1313 | J35: ='0_Parametros'!B7 -> 10 | K35: =(I35-SUM($J$2:$J$57))*G35/H35 -> 0.81482016 | L35: =INT(K35) -> 0 | M35: =K35-L35 -> 0.81482016 | N35: =COUNTIF($M$2:$M$57,">"&M35)+COUNTIF($M$2:M35,M35) -> 8 | O35: =J35+L35+IF(N35<=I35-SUM($J$2:$J$57)-SUM($L$2:$L$57),1,0) -> 11
A36: Bogotá | B36: BOGOTA D.C. | C36: SUBSIDIADO | D36: FEMENINO | E36: 30-39 | F36: URBANO | G36: 132456 | H36: ='1_Departamento_n'!C2 -> 7780253 | I36: ='1_Departamento_n'!H2 -> 1313 | J36: ='0_Parametros'!B7 -> 10 | K36: =(I36-SUM($J$2:$J$57))*G36/H36 -> 12.819553 | L36: =INT(K36) -> 12 | M36: =K36-L36 -> 0.8195533 | N36: =COUNTIF($M$2:$M$57,">"&M36)+COUNTIF($M$2:M36,M36) -> 7 | O36: =J36+L36+IF(N36<=I36-SUM($J$2:$J$57)-SUM($L$2:$L$57),1,0) -> 23
A37: Bogotá | B37: BOGOTA D.C. | C37: SUBSIDIADO | D37: FEMENINO | E37: 30-39 | F37: RURAL | G37: 5368 | H37: ='1_Departamento_n'!C2 -> 7780253 | I37: ='1_Departamento_n'!H2 -> 1313 | J37: ='0_Parametros'!B7 -> 10 | K37: =(I37-SUM($J$2:$J$57))*G37/H37 -> 0.51953375 | L37: =INT(K37) -> 0 | M37: =K37-L37 -> 0.51953375 | N37: =COUNTIF($M$2:$M$57,">"&M37)+COUNTIF($M$2:M37,M37) -> 19 | O37: =J37+L37+IF(N37<=I37-SUM($J$2:$J$57)-SUM($L$2:$L$57),1,0) -> 11
A38: Bogotá | B38: BOGOTA D.C. | C38: SUBSIDIADO | D38: FEMENINO | E38: 40-49 | F38: URBANO | G38: 115123 | H38: ='1_Departamento_n'!C2 -> 7780253 | I38: ='1_Departamento_n'!H2 -> 1313 | J38: ='0_Parametros'!B7 -> 10 | K38: =(I38-SUM($J$2:$J$57))*G38/H38 -> 11.142005 | L38: =INT(K38) -> 11 | M38: =K38-L38 -> 0.14200515 | N38: =COUNTIF($M$2:$M$57,">"&M38)+COUNTIF($M$2:M38,M38) -> 53 | O38: =J38+L38+IF(N38<=I38-SUM($J$2:$J$57)-SUM($L$2:$L$57),1,0) -> 21
A39: Bogotá | B39: BOGOTA D.C. | C39: SUBSIDIADO | D39: FEMENINO | E39: 40-49 | F39: RURAL | G39: 3302 | H39: ='1_Departamento_n'!C2 -> 7780253 | I39: ='1_Departamento_n'!H2 -> 1313 | J39: ='0_Parametros'!B7 -> 10 | K39: =(I39-SUM($J$2:$J$57))*G39/H39 -> 0.31957907 | L39: =INT(K39) -> 0 | M39: =K39-L39 -> 0.31957907 | N39: =COUNTIF($M$2:$M$57,">"&M39)+COUNTIF($M$2:M39,M39) -> 41 | O39: =J39+L39+IF(N39<=I39-SUM($J$2:$J$57)-SUM($L$2:$L$57),1,0) -> 10
A40: Bogotá | B40: BOGOTA D.C. | C40: SUBSIDIADO | D40: FEMENINO | E40: 50-59 | F40: URBANO | G40: 105828 | H40: ='1_Departamento_n'!C2 -> 7780253 | I40: ='1_Departamento_n'!H2 -> 1313 | J40: ='0_Parametros'!B7 -> 10 | K40: =(I40-SUM($J$2:$J$57))*G40/H40 -> 10.242403 | L40: =INT(K40) -> 10 | M40: =K40-L40 -> 0.24240266 | N40: =COUNTIF($M$2:$M$57,">"&M40)+COUNTIF($M$2:M40,M40) -> 48 | O40: =J40+L40+IF(N40<=I40-SUM($J$2:$J$57)-SUM($L$2:$L$57),1,0) -> 20
...

Sheet 3_Chequeo_Cuadre
A1: region | B1: departamento | C1: meta | D1: asignado | E1: diferencia
A2: Bogotá | B2: BOGOTA D.C. | C2: ='1_Departamento_n'!H2 -> 1313 | D2: =SUM('2_Asignacion_Celda'!O2:O57) -> 1313 | E2: =D2-C2 -> 0
A3: Caribe | B3: ATLANTICO | C3: ='1_Departamento_n'!H3 -> 1313 | D3: =SUM('2_Asignacion_Celda'!O58:O113) -> 1313 | E3: =D3-C3 -> 0
A4: Caribe | B4: BOLIVAR | C4: ='1_Departamento_n'!H4 -> 1312 | D4: =SUM('2_Asignacion_Celda'!O114:O169) -> 1312 | E4: =D4-C4 -> 0
A5: Caribe | B5: CESAR | C5: ='1_Departamento_n'!H5 -> 1312 | D5: =SUM('2_Asignacion_Celda'!O170:O225) -> 1312 | E5: =D5-C5 -> 0
A6: Caribe | B6: CORDOBA | C6: ='1_Departamento_n'!H6 -> 1312 | D6: =SUM('2_Asignacion_Celda'!O226:O281) -> 1312 | E6: =D6-C6 -> 0
A7: Caribe | B7: LA GUAJIRA | C7: ='1_Departamento_n'!H7 -> 1312 | D7: =SUM('2_Asignacion_Celda'!O282:O337) -> 1312 | E7: =D7-C7 -> 0
A8: Caribe | B8: MAGDALENA | C8: ='1_Departamento_n'!H8 -> 1312 | D8: =SUM('2_Asignacion_Celda'!O338:O393) -> 1312 | E8: =D8-C8 -> 0
A9: Caribe | B9: SAN ANDRES | C9: ='1_Departamento_n'!H9 -> 1293 | D9: =SUM('2_Asignacion_Celda'!O394:O449) -> 1293 | E9: =D9-C9 -> 0
A10: Caribe | B10: SUCRE | C10: ='1_Departamento_n'!H10 -> 1312 | D10: =SUM('2_Asignacion_Celda'!O450:O505) -> 1312 | E10: =D10-C10 -> 0
A11: Central | B11: ANTIOQUIA | C11: ='1_Departamento_n'!H11 -> 1313 | D11: =SUM('2_Asignacion_Celda'!O506:O561) -> 1313 | E11: =D11-C11 -> 0
A12: Central | B12: CALDAS | C12: ='1_Departamento_n'!H12 -> 1312 | D12: =SUM('2_Asignacion_Celda'!O562:O617) -> 1312 | E12: =D12-C12 -> 0
A13: Central | B13: CAQUETA | C13: ='1_Departamento_n'!H13 -> 1310 | D13: =SUM('2_Asignacion_Celda'!O618:O673) -> 1310 | E13: =D13-C13 -> 0
A14: Central | B14: HUILA | C14: ='1_Departamento_n'!H14 -> 1312 | D14: =SUM('2_Asignacion_Celda'!O674:O729) -> 1312 | E14: =D14-C14 -> 0
A15: Central | B15: QUINDIO | C15: ='1_Departamento_n'!H15 -> 1311 | D15: =SUM('2_Asignacion_Celda'!O730:O785) -> 1311 | E15: =D15-C15 -> 0
A16: Central | B16: RISARALDA | C16: ='1_Departamento_n'!H16 -> 1312 | D16: =SUM('2_Asignacion_Celda'!O786:O841) -> 1312 | E16: =D16-C16 -> 0
A17: Central | B17: TOLIMA | C17: ='1_Departamento_n'!H17 -> 1312 | D17: =SUM('2_Asignacion_Celda'!O842:O897) -> 1312 | E17: =D17-C17 -> 0
A18: Oriental | B18: BOYACA | C18: ='1_Departamento_n'!H18 -> 1312 | D18: =SUM('2_Asignacion_Celda'!O898:O953) -> 1312 | E18: =D18-C18 -> 0
A19: Oriental | B19: CUNDINAMARCA | C19: ='1_Departamento_n'!H19 -> 1313 | D19: =SUM('2_Asignacion_Celda'!O954:O1009) -> 1313 | E19: =D19-C19 -> 0
A20: Oriental | B20: META | C20: ='1_Departamento_n'!H20 -> 1312 | D20: =SUM('2_Asignacion_Celda'!O1010:O1065) -> 1312 | E20: =D20-C20 -> 0
A21: Oriental | B21: NORTE DE SANTANDER | C21: ='1_Departamento_n'!H21 -> 1312 | D21: =SUM('2_Asignacion_Celda'!O1066:O1121) -> 1312 | E21: =D21-C21 -> 0
A22: Oriental | B22: SANTANDER | C22: ='1_Departamento_n'!H22 -> 1312 | D22: =SUM('2_Asignacion_Celda'!O1122:O1177) -> 1312 | E22: =D22-C22 -> 0
A23: Orinoquía-Amazonía | B23: AMAZONAS | C23: ='1_Departamento_n'!H23 -> 1297 | D23: =SUM('2_Asignacion_Celda'!O1178:O1233) -> 1297 | E23: =D23-C23 -> 0
A24: Orinoquía-Amazonía | B24: ARAUCA | C24: ='1_Departamento_n'!H24 -> 1309 | D24: =SUM('2_Asignacion_Celda'!O1234:O1289) -> 1309 | E24: =D24-C24 -> 0
A25: Orinoquía-Amazonía | B25: CASANARE | C25: ='1_Departamento_n'!H25 -> 1310 | D25: =SUM('2_Asignacion_Celda'!O1290:O1345) -> 1310 | E25: =D25-C25 -> 0
A26: Orinoquía-Amazonía | B26: GUAINIA | C26: ='1_Departamento_n'!H26 -> 1291 | D26: =SUM('2_Asignacion_Celda'!O1346:O1401) -> 1291 | E26: =D26-C26 -> 0
A27: Orinoquía-Amazonía | B27: GUAVIARE | C27: ='1_Departamento_n'!H27 -> 1299 | D27: =SUM('2_Asignacion_Celda'!O1402:O1457) -> 1299 | E27: =D27-C27 -> 0
A28: Orinoquía-Amazonía | B28: PUTUMAYO | C28: ='1_Departamento_n'!H28 -> 1309 | D28: =SUM('2_Asignacion_Celda'!O1458:O1513) -> 1309 | E28: =D28-C28 -> 0
A29: Orinoquía-Amazonía | B29: VAUPES | C29: ='1_Departamento_n'!H29 -> 1278 | D29: =SUM('2_Asignacion_Celda'!O1514:O1569) -> 1278 | E29: =D29-C29 -> 0
A30: Orinoquía-Amazonía | B30: VICHADA | C30: ='1_Departamento_n'!H30 -> 1299 | D30: =SUM('2_Asignacion_Celda'!O1570:O1625) -> 1299 | E30: =D30-C30 -> 0
A31: Pacífica | B31: CAUCA | C31: ='1_Departamento_n'!H31 -> 1312 | D31: =SUM('2_Asignacion_Celda'!O1626:O1681) -> 1312 | E31: =D31-C31 -> 0
A32: Pacífica | B32: CHOCO | C32: ='1_Departamento_n'!H32 -> 1310 | D32: =SUM('2_Asignacion_Celda'!O1682:O1737) -> 1310 | E32: =D32-C32 -> 0
A33: Pacífica | B33: NARINO | C33: ='1_Departamento_n'!H33 -> 1312 | D33: =SUM('2_Asignacion_Celda'!O1738:O1793) -> 1312 | E33: =D33-C33 -> 0
A34: Pacífica | B34: VALLE | C34: ='1_Departamento_n'!H34 -> 1313 | D34: =SUM('2_Asignacion_Celda'!O1794:O1849) -> 1313 | E34: =D34-C34 -> 0

Sheet 4_Resumen_Sexo
A1: sexo | B1: poblacion | C1: meta | D1: porcentaje
A2: FEMENINO | B2: =SUMIF('2_Asignacion_Celda'!D2:D1849,A2,'2_Asignacion_Celda'!G2:G1849) -> 25775997 | C2: =SUMIF('2_Asignacion_Celda'!D2:D1849,A2,'2_Asignacion_Celda'!O2:O1849) -> 21768 | D2: =C2/SUM(C2:C3) -> 0.50420402
A3: MASCULINO | B3: =SUMIF('2_Asignacion_Celda'!D2:D1849,A3,'2_Asignacion_Celda'!G2:G1849) -> 24392749 | C3: =SUMIF('2_Asignacion_Celda'!D2:D1849,A3,'2_Asignacion_Celda'!O2:O1849) -> 21405 | D3: =C3/SUM(C2:C3) -> 0.49579598

Sheet 5_Resumen_Edad
A1: edad | B1: poblacion | C1: meta | D1: porcentaje
A2: 00-09 | B2: =SUMIF('2_Asignacion_Celda'!E2:E1849,A2,'2_Asignacion_Celda'!G2:G1849) -> 5744359 | C2: =SUMIF('2_Asignacion_Celda'!E2:E1849,A2,'2_Asignacion_Celda'!O2:O1849) -> 5955 | D2: =C2/SUM(C2:C8) -> 0.13793343
A3: 10-19 | B3: =SUMIF('2_Asignacion_Celda'!E2:E1849,A3,'2_Asignacion_Celda'!G2:G1849) -> 7461675 | C3: =SUMIF('2_Asignacion_Celda'!E2:E1849,A3,'2_Asignacion_Celda'!O2:O1849) -> 6686 | D3: =C3/SUM(C2:C8) -> 0.15486531
A4: 20-29 | B4: =SUMIF('2_Asignacion_Celda'!E2:E1849,A4,'2_Asignacion_Celda'!G2:G1849) -> 7965209 | C4: =SUMIF('2_Asignacion_Celda'!E2:E1849,A4,'2_Asignacion_Celda'!O2:O1849) -> 6534 | D4: =C4/SUM(C2:C8) -> 0.15134459
A5: 30-39 | B5: =SUMIF('2_Asignacion_Celda'!E2:E1849,A5,'2_Asignacion_Celda'!G2:G1849) -> 7926389 | C5: =SUMIF('2_Asignacion_Celda'!E2:E1849,A5,'2_Asignacion_Celda'!O2:O1849) -> 6419 | D5: =C5/SUM(C2:C8) -> 0.14868089
A6: 40-49 | B6: =SUMIF('2_Asignacion_Celda'!E2:E1849,A6,'2_Asignacion_Celda'!G2:G1849) -> 6751667 | C6: =SUMIF('2_Asignacion_Celda'!E2:E1849,A6,'2_Asignacion_Celda'!O2:O1849) -> 5815 | D6: =C6/SUM(C2:C8) -> 0.13469066
A7: 50-59 | B7: =SUMIF('2_Asignacion_Celda'!E2:E1849,A7,'2_Asignacion_Celda'!G2:G1849) -> 5600016 | C7: =SUMIF('2_Asignacion_Celda'!E2:E1849,A7,'2_Asignacion_Celda'!O2:O1849) -> 5248 | D7: =C7/SUM(C2:C8) -> 0.12155745
A8: 60 o más | B8: =SUMIF('2_Asignacion_Celda'!E2:E1849,A8,'2_Asignacion_Celda'!G2:G1849) -> 8719431 | C8: =SUMIF('2_Asignacion_Celda'!E2:E1849,A8,'2_Asignacion_Celda'!O2:O1849) -> 6516 | D8: =C8/SUM(C2:C8) -> 0.15092766

Sheet 6_Resumen_Zona
A1: zona | B1: poblacion | C1: meta | D1: porcentaje
A2: URBANO | B2: =SUMIF('2_Asignacion_Celda'!F2:F1849,A2,'2_Asignacion_Celda'!G2:G1849) -> 40083538 | C2: =SUMIF('2_Asignacion_Celda'!F2:F1849,A2,'2_Asignacion_Celda'!O2:O1849) -> 25759 | D2: =C2/SUM(C2:C3) -> 0.59664605
A3: RURAL | B3: =SUMIF('2_Asignacion_Celda'!F2:F1849,A3,'2_Asignacion_Celda'!G2:G1849) -> 10085208 | C3: =SUMIF('2_Asignacion_Celda'!F2:F1849,A3,'2_Asignacion_Celda'!O2:O1849) -> 17414 | D3: =C3/SUM(C2:C3) -> 0.40335395

Sheet 7_Resumen_Regimen
A1: regimen | B1: poblacion | C1: meta | D1: porcentaje
A2: CONTRIBUTIVO | B2: =SUMIF('2_Asignacion_Celda'!C2:C1849,A2,'2_Asignacion_Celda'!G2:G1849) -> 23224623 | C2: =SUMIF('2_Asignacion_Celda'!C2:C1849,A2,'2_Asignacion_Celda'!O2:O1849) -> 17505 | D2: =C2/SUM(C2:C3) -> 0.40546175
A3: SUBSIDIADO | B3: =SUMIF('2_Asignacion_Celda'!C2:C1849,A3,'2_Asignacion_Celda'!G2:G1849) -> 26944123 | C3: =SUMIF('2_Asignacion_Celda'!C2:C1849,A3,'2_Asignacion_Celda'!O2:O1849) -> 25668 | D3: =C3/SUM(C2:C3) -> 0.59453825

Sheet 8_Resumen_Region
A1: region | B1: poblacion | C1: meta | D1: porcentaje
A2: Bogotá | B2: =SUMIF('2_Asignacion_Celda'!A2:A1849,A2,'2_Asignacion_Celda'!G2:G1849) -> 7780253 | C2: =SUMIF('2_Asignacion_Celda'!A2:A1849,A2,'2_Asignacion_Celda'!O2:O1849) -> 1313 | D2: =C2/SUM(C2:C7) -> 0.030412526
A3: Caribe | B3: =SUMIF('2_Asignacion_Celda'!A2:A1849,A3,'2_Asignacion_Celda'!G2:G1849) -> 11666255 | C3: =SUMIF('2_Asignacion_Celda'!A2:A1849,A3,'2_Asignacion_Celda'!O2:O1849) -> 10478 | D3: =C3/SUM(C2:C7) -> 0.24269798
A4: Central | B4: =SUMIF('2_Asignacion_Celda'!A2:A1849,A4,'2_Asignacion_Celda'!G2:G1849) -> 12414228 | C4: =SUMIF('2_Asignacion_Celda'!A2:A1849,A4,'2_Asignacion_Celda'!O2:O1849) -> 9182 | D4: =C4/SUM(C2:C7) -> 0.21267922
A5: Oriental | B5: =SUMIF('2_Asignacion_Celda'!A2:A1849,A5,'2_Asignacion_Celda'!G2:G1849) -> 9033646 | C5: =SUMIF('2_Asignacion_Celda'!A2:A1849,A5,'2_Asignacion_Celda'!O2:O1849) -> 6561 | D5: =C5/SUM(C2:C7) -> 0.15196998
A6: Orinoquía-Amazonía | B6: =SUMIF('2_Asignacion_Celda'!A2:A1849,A6,'2_Asignacion_Celda'!G2:G1849) -> 1428022 | C6: =SUMIF('2_Asignacion_Celda'!A2:A1849,A6,'2_Asignacion_Celda'!O2:O1849) -> 10392 | D6: =C6/SUM(C2:C7) -> 0.240706
A7: Pacífica | B7: =SUMIF('2_Asignacion_Celda'!A2:A1849,A7,'2_Asignacion_Celda'!G2:G1849) -> 7846342 | C7: =SUMIF('2_Asignacion_Celda'!A2:A1849,A7,'2_Asignacion_Celda'!O2:O1849) -> 5247 | D7: =C7/SUM(C2:C7) -> 0.12153429
